<?xml version="1.0" ?>
<sdf version="1.8" xmlns:xacro="http://ros.org/wiki/xacro">
  <model name='sam_bot' canonical_link='base_link'>

    <!-- Define robot constants -->
    <xacro:property name="base_width" value="0.36195"/>
    <xacro:property name="base_length" value="0.4318"/>
    <xacro:property name="base_height" value="0.2889"/>

    <xacro:property name="wheel_radius" value="0.0700"/>
    <xacro:property name="wheel_width" value="0.0370"/>
    <xacro:property name="wheel_ygap" value="0.02500"/>
    <xacro:property name="wheel_zoff" value="0.11945"/>
    <xacro:property name="wheel_xoff" value="0.1778"/>

    <!-- Define some commonly used inertial properties  -->
    <xacro:macro name="box_inertia" params="m w h d">
      <inertial>
        <pose>0 0 0 ${pi/2} 0 ${pi/2}</pose>
        <mass>${m}</mass>
        <inertia>
          <ixx>${(m/12) * (h*h + d*d)}</ixx>
          <ixy>0.0</ixy>
          <ixz>0.0</ixz>
          <iyy>${(m/12) * (w*w + d*d)}</iyy>
          <iyz>0.0</iyz>
          <izz>${(m/12) * (w*w + h*h)}</izz>
        </inertia>
      </inertial>
    </xacro:macro>

    <xacro:macro name="cylinder_inertia" params="m r h">
      <inertial>
        <pose>0 0 0 ${pi/2} 0 0</pose>
        <mass>${m}</mass>
        <inertia>
          <ixx>${(m/12) * (3*r*r + h*h)}</ixx>
          <ixy>0.0</ixy>
          <ixz>0.0</ixz>
          <iyy>${(m/12) * (3*r*r + h*h)}</iyy>
          <iyz>0.0</iyz>
          <izz>${(m/2) * (r*r)}</izz>
        </inertia>
      </inertial>
    </xacro:macro>

    <!-- Robot Base -->
    <link name='base_link'>
      <must_be_base_link>true</must_be_base_link>
      <visual name="base_link_visual">
        <geometry>
          <box><size>
            ${base_length} ${base_width} ${base_height}
          </size></box>
        </geometry>
        <material>
          <ambient>0 1 1 1</ambient>
          <diffuse>0 1 1 1</diffuse>
        </material>
      </visual>

      <collision name="base_link_collision">
        <geometry>
          <box><size>
            ${base_length} ${base_width} ${base_height}
          </size></box>
        </geometry>
      </collision>
    </link>

    <!-- Robot Footprint -->
    <link name='base_footprint'>
      <pose relative_to="base_joint"/>
      <xacro:box_inertia m="15" w="${base_width}" d="${base_length}" h="${base_height}"/>
    </link>

    <joint name='base_joint' type='fixed'>
      <parent>base_link</parent>
      <child>base_footprint</child>
      <pose relative_to="base_link">0.0 0.0 ${-(wheel_radius+wheel_zoff)} 0 0 0</pose>
    </joint>


    <!-- Wheels -->
    <xacro:macro name="wheel" params="prefix x_reflect y_reflect">
      <link name="${prefix}_link">
        <pose relative_to="${prefix}_joint"/>

        <visual name="${prefix}_link_visual">
          <pose relative_to="${prefix}_link">0 0 0 ${pi/2} 0 0</pose>
          <geometry>
            <cylinder>
              <radius>${wheel_radius}</radius>
              <length>${wheel_width}</length>
            </cylinder>
          </geometry>
          <material>
            <ambient>0.3 0.3 0.3 1.0</ambient>
            <diffuse>0.7 0.7 0.7 1.0</diffuse>
          </material>
        </visual>

        <collision name="${prefix}_link_collision">
          <pose relative_to="${prefix}_link">0 0 0 ${pi/2} 0 0</pose>
          <geometry>
            <cylinder>
              <radius>${wheel_radius}</radius>
              <length>${wheel_width}</length>
            </cylinder>
          </geometry>
        </collision>

        <xacro:cylinder_inertia m="0.5" r="${wheel_radius}" h="${wheel_width}"/>
      </link>

      <joint name="${prefix}_joint" type="revolute">
        <parent>base_link</parent>
        <child>${prefix}_link</child>
        <pose relative_to="base_link">${x_reflect*wheel_xoff} ${y_reflect*(base_width/2+wheel_ygap)} ${-wheel_zoff} 0 0 0</pose>
        <axis>
          <xyz>0 1 0</xyz>
          <limit>
            <lower>-inf</lower>
            <upper>inf</upper>
          </limit>
        </axis>
      </joint>
    </xacro:macro>

    <xacro:wheel prefix="drivewhl_FL" x_reflect=" 1" y_reflect=" 1" />
    <xacro:wheel prefix="drivewhl_FR" x_reflect=" 1" y_reflect="-1" />
    <xacro:wheel prefix="drivewhl_BL" x_reflect="-1" y_reflect=" 1" />
    <xacro:wheel prefix="drivewhl_BR" x_reflect="-1" y_reflect="-1" />
  </model>
</sdf>